---
title: 'Exception Handling'
---

#### Exception Handling

Exception is a condition that is caused by a run-time error in the program. When the java interpreter encounter an error such as dividing an integer by Zero. it creates an exception object and throws it (i.e. inform us that an error has occured).

###### common java exceptions:
- ArithmeticException
- ArrayIndexOutOfBoundException
- ArrayStoreException
- FileNotFoundException
- IOException
- NullPointerException
- NumberFormatException
- OutOfMemoryException
- SecurityException
- StackOverflowException
- StringIndexOutOfBoundException

---

#### Syntax of exception handling code

```java
try{
	// here exception may occur
}catch(exception-type e){
	// here occured exception is handled
}
```

#### throw, throws, finally

```java
class Division {
    public static void main(String[] args)
    {
        int a = 10, b = 5, c = 5, result;
        try {
            result = a / (b - c);
            System.out.println("result" + result);
        }catch (ArithmeticException e) { //üëàüèª
            System.out.println("Exception caught:Division by zero");
        }finally { // üëàüèª
            System.out.println("I am in final block");
        }
    }
}
```
```bash
Exception caught:Division by zero
I am in final block
```

```java
class ThrowsExecp {
 
    // This method throws an exception
    // to be handled
    // by caller or caller
    // of caller and so on.
    static void fun() throws IllegalAccessException { // üëàüèª
        System.out.println("Inside fun(). ");
        throw new IllegalAccessException("demo"); // üëàüèª
    }
 
    // This is a caller function
    public static void main(String args[])
    {
        try {
            fun();
        }
        catch (IllegalAccessException e) {
            System.out.println("caught in main.");
        }
    }
}
```


```bash
Inside fun(). 
caught in main.
```